<?xml version="1.0" ?>

<robot name="raio_makuin">
    <material name="white">
        <color rgba="1 1 1 1"/>
    </material>
    <material name="orange">
        <color rgba="1 0.3 0.1 1"/>
    </material>
    <material name="blue">
        <color rgba="0.2 0.2 1 1"/>
    </material>
    <material name="black">
        <color rgba="0 0 0 1"/>
    </material>

    <!-- Link - chassis -->
    <link name="link_chassis">
        <inertial>
            <mass value="10" />
            <origin xyz="0 0 0.3" rpy="0 0 0" />
            <inertia ixx="1.5417" ixy="0" ixz="0" iyy="3.467" iyz="0" izz="4.742" />
        </inertial>

        <collision>
            <geometry>
                <box size="2 1.3 0.4" />
            </geometry>
        </collision>

        <visual>
            <geometry>
                <!-- <box size="2 1.3 0.4" /> -->
                <mesh filename="package://robot_description/meshes/chassis.stl" />
            </geometry>
            <material name="Red">
                <color rgba="1 0 0 1" />
            </material>
        </visual>
    </link>

      <!-- Joint - chassis / left wheel -->
    <joint name="joint_chassis_left_wheel" type="continuous">
        <origin rpy="-1.57079 0 0" xyz="-0.5 0.65 0" />
        <child link="link_left_wheel" />
        <parent link="link_chassis" />
        <axis rpy="0 0 0" xyz="0 0 1" />
        <limit effort="10000" velocity="1000" />
        <joint_properties damping="1.0" friction="1.0" />
    </joint>

    <!-- Link - left wheel -->
    <link name="link_left_wheel">
        <inertial>
            <mass value="1" />
            <origin xyz="0 0 0" rpy="0 0 0" />
            <inertia ixx="0.002526666666667" ixy="0" ixz="0" iyy="0.002526666666667" iyz="0" izz="0.005"/>
        </inertial>

        <collision>
            <origin rpy="0 0 0" xyz="0 0 0.18 " />
            <geometry>
                <!-- <cylinder length="0.12" radius="0.4"/> -->
                <mesh filename="package://robot_description/meshes/wheel.stl" />
            </geometry>
        </collision>
        <visual>
            <origin rpy="0 0 1.57079" xyz="0 0 0.18 " />
            <geometry>
                <cylinder length="0.12" radius="0.4"/>
            </geometry>
            <material name="black"></material>
        </visual>

        <collision>
            <origin rpy="0 0 0" xyz="0 0 0.06 " />
            <geometry>
                <cylinder length="0.12" radius="0.08"/>
            </geometry>
        </collision>
        <visual>
            <origin rpy="0 0 0" xyz="0 0 0.06 " />
            <geometry>
                <cylinder length="0.12" radius="0.08"/>
            </geometry>
        </visual>
    </link>

    <!-- Joint - chassis / right wheel -->
    <joint name="joint_chassis_right_wheel" type="continuous">
        <origin rpy="1.57079 0 0" xyz="-0.5 -0.65 0" />
        <child link="link_right_wheel" />
        <parent link="link_chassis" />
        <axis rpy="0 0 0" xyz="0 0 1" />
        <limit effort="10000" velocity="1000" />
        <joint_properties damping="1.0" friction="1.0" />
    </joint>

    <!-- Link - right wheel -->
    <link name="link_right_wheel">
        <inertial>
            <mass value="1" />
            <origin xyz="0 0 0" rpy="0 0 0" />
            <inertia ixx="0.002526666666667" ixy="0" ixz="0" iyy="0.002526666666667" iyz="0" izz="0.005"/>
        </inertial>

        <collision>
            <origin rpy="0 0 0" xyz="0 0 0.18 " />
            <geometry>
                <cylinder length="0.12" radius="0.4"/>
            </geometry>
        </collision>
        <visual>
            <origin rpy="0 0 1.57079" xyz="0 0 0.18 " />
            <geometry>
                <!-- <cylinder length="0.12" radius="0.4"/> -->
                <mesh filename="package://robot_description/meshes/wheel.stl" />
            </geometry>
            <material name="black"></material>
        </visual>

        <collision>
            <origin rpy="0 0 0" xyz="0 0 0.06 " />
            <geometry>
                <cylinder length="0.12" radius="0.08"/>
            </geometry>
        </collision>
        <visual>
            <origin rpy="0 0 0" xyz="0 0 0.06 " />
            <geometry>
                <cylinder length="0.12" radius="0.08"/>
            </geometry>
        </visual>
    </link>



    <!-- Joint - chassis / right wheel line -->
    <joint name="joint_chassis_right_wheel_line" type="continuous">
        <origin rpy="0 0 0" xyz="0 0 0.27" />
        <child link="link_right_wheel_line" />
        <parent link="link_right_wheel" />
        <axis rpy="0 0 0" xyz="0 0 1" />
        <limit effort="10000" velocity="1000" />
        <joint_properties damping="1.0" friction="1.0" />
    </joint>

    <!-- Link - right wheel -->
    <link name="link_right_wheel_line">
        <inertial>
            <mass value="1" />
            <origin xyz="0 0 0" rpy="0 0 0" />
            <inertia ixx="0.002526666666667" ixy="0" ixz="0" iyy="0.002526666666667" iyz="0" izz="0.005"/>
        </inertial>

        <collision>
            <geometry>
                <box size="0.05 0.7 0.01" />
            </geometry>
        </collision>

        <visual>
            <geometry>
                <box size="0.05 0.7 0.01" />
            </geometry>
            <material name="white"></material>
            
        </visual>
    </link>


   <!-- Joint - chassis / left wheel line -->
    <joint name="joint_chassis_left_wheel_line" type="continuous">
        <origin rpy="0 0 0" xyz="0 0 0.27" />
        <child link="link_left_wheel_line" />
        <parent link="link_left_wheel" />
        <axis rpy="0 0 0" xyz="0 0 1" />
        <limit effort="10000" velocity="1000" />
        <joint_properties damping="1.0" friction="1.0" />
    </joint>

    <!-- Link - right wheel -->
    <link name="link_left_wheel_line">
        <inertial>
            <mass value="1" />
            <origin xyz="0 0 0" rpy="0 0 0" />
            <inertia ixx="0.002526666666667" ixy="0" ixz="0" iyy="0.002526666666667" iyz="0" izz="0.005"/>
        </inertial>

        <collision>
            <geometry>
                <box size="0.05 0.7 0.01" />
            </geometry>
        </collision>

        <visual>
            <geometry>
                <box size="0.05 0.7 0.01" />
            </geometry>
            <material name="white"></material>
            
        </visual>
    </link>



    <!-- Joint - chassis / middle ball -->
    <joint name="joint_chassis_middle_ball" type="continuous">
        <origin rpy="0 0 0" xyz="0.75 0 -0.15" />
        <child link="link_middle_ball" />
        <parent link="link_chassis" />
        <axis rpy="0 0 0" xyz="1 0 0" />
        <limit effort="10000" velocity="1000" />
        <joint_properties damping="1.0" friction="1.0" />
    </joint>

    <!-- Link - middle ball -->
    <link name="link_middle_ball">
        <inertial>
            <mass value="1" />
            <origin xyz="0 0 0" rpy="0 0 0" />
            <inertia ixx="0.002526666666667" ixy="0" ixz="0" iyy="0.002526666666667" iyz="0" izz="0.005"/>
        </inertial>

        <collision>
            <origin rpy="0 0 0" xyz="0 0 0.18 " />
            <geometry>
                <sphere radius="0.17"/>
            </geometry>
        </collision>
        <visual>
            <origin rpy="0 0 0" xyz="0 0 0 " />
            <geometry>
                <sphere radius="0.17"/>
            </geometry>
            <material name="blue"/>
            
        </visual>

        <collision>
            <origin rpy="0 0 0" xyz="0 0 0.06 " />
            <geometry>
                <sphere radius="0.17"/>
            </geometry>
        </collision>
        <visual>
            <origin rpy="0 0 0" xyz="0 0 0.06 " />
            <geometry>
                <sphere radius="0.17"/>
            </geometry>
        </visual>
    </link>
    <!-- <material name="blue"/> -->


    <!-- Joint - chassis / middle ball2 -->
    <joint name="joint_chassis_middle_ball2" type="continuous">
        <origin rpy="0 0 0" xyz="0 0 -0.14" />
        <child link="link_middle_ball2" />
        <parent link="link_middle_ball" />
        <axis rpy="0 0 0" xyz="1 0 0" />
        <limit effort="10000" velocity="1000" />
        <joint_properties damping="1.0" friction="1.0" />
    </joint>

    <!-- Link - middle ball2 -->
    <link name="link_middle_ball2">
        <inertial>
            <mass value="1" />
            <origin xyz="0 0 0" rpy="0 0 0" />
            <inertia ixx="0.002526666666667" ixy="0" ixz="0" iyy="0.002526666666667" iyz="0" izz="0.005"/>
        </inertial>

        <collision>
            <origin rpy="0 0 0" xyz="0 0 0 " />
            <geometry>
                <sphere radius="0.08"/>
            </geometry>
        </collision>
        <visual>
            <origin rpy="0 0 0" xyz="0 0 0 " />
            <geometry>
                <sphere radius="0.08"/>
            </geometry>
            <material name="white"></material>
        </visual>

        <collision>
            <origin rpy="0 0 0" xyz="0 0 0 " />
            <geometry>
                <sphere radius="0.08"/>
            </geometry>
        </collision>
        <visual>
            <origin rpy="0 0 0" xyz="0 0 0 " />
            <geometry>
                <sphere radius="0.08"/>
            </geometry>
        </visual>
    </link>
    <!-- <material name="blue"/> -->

</robot>